Workbook

Sheet Overview
A1: SOW managed services adoption model
A2: Each phase builds on the last. Win on the transactional before claiming the strategic. Attempting Phases 3–4 before Phases 1–2 are demonstrably working is the most common failure mode.
A3: Phase | B3: Timeline | C3: Objective | D3: Key focus / mandate
A4: Phase 1 — Worker classification | B4: 2–4 months | C4: Establish ground truth on what's actually happening in the current state. Surface savings leakage and misclassified buying channels without threatening ownership. | D4: Establish ground truth
A5: Phase 2 — Administrative processing | B5: 4–8 months | C5: Take ownership of execution and record-keeping without touching sourcing decisions. Demonstrate operational reliability — the credibility that earns the right to Phase 3. | D5: Own execution, not sourcing
A6: Phase 3 — Sourcing assistance (tail-end spend) | B6: 6–12 months | C6: Take the lead on sourcing activity below a defined spend threshold. Demonstrate that the managed services function can do sourcing well — not just process it. Build the PSL. | D6: Lead sub-threshold sourcing
A7: Phase 4 — RFx support and strategic sourcing partnership | B7: 12+ months | C7: Extend capabilities into competitive sourcing events and strategic spend. The patterning model: managed services runs the process, Procurement owns the decision. | D7: Partner on strategic spend
A9: Change management notes
A10: Mandate question | B10: Must be resolved before Phase 3. Without it, shared services becomes a center of excellence that sends recommendations nobody has to follow — expensive advice-giving with a headcount budget.
A11: Sequencing logic | B11: Phases 1–2 should be largely complete and demonstrably working before Phase 3 begins. The credibility from Phase 2 is what makes the Phase 3 ask politically survivable.
A12: Sponsor role | B12: Strong sponsors know the value of scale only materializes when the scale is real — and real means no opt-out. They often underestimate the political capital needed to enforce it in months 1–18.
A13: Identity problem | B13: Procurement leaders who resist aren't just being territorial — they're protecting their professional identity. Frame each phase as bandwidth relief, not displacement, until Phase 4 credibility makes it unnecessary.

Sheet Phase 1 — Classification
A1: Phase 1 — Worker classification
A2: Timeline: 2–4 months | Focus: Establish ground truth
A3: Objective
B4: Establish ground truth on what's actually happening in the current state. Surface savings leakage and misclassified buying channels without threatening ownership.
A5: Stakeholder dynamics
B6: Low threat to Procurement — framed as diagnosis, not displacement. Hiring managers largely unaffected. Sponsors use this phase to build the business case for mandate.
A7: Key activities
A8: 1. | B8: Audit active SOWs against classification criteria (project-based vs. staff aug, fixed deliverable vs. T&M)
A9: 2. | B9: Flag SOWs that should have been routed through contingent/staffing channels
A10: 3. | B10: Quantify savings leakage: rate variance, missing competitive tension, auto-renewals, scope creep with no price adjustment
A11: 4. | B11: Deploy tooling to systematize classification (intake forms, decision trees, VMS/platform tagging)
A12: 5. | B12: Establish baseline data: spend by supplier, category, business unit, contract type
A13: Tooling
A14: 1. | B14: SOW intake/classification tool (rule-based scoring)
A15: 2. | B15: Spend analytics / data normalization layer
A16: 3. | B16: Stakeholder-facing dashboard (visibility only — no control)
A17: Success metrics
A18: ✓ | B18: % of active SOWs classified
A19: ✓ | B19: Estimated savings leakage identified ($)
A20: ✓ | B20: Misrouted contracts flagged and documented
A21: ✓ | B21: Baseline spend and supplier count established
A22: Resistance signals — watch for these
A23: ! | B23: "Our SOWs are different / too complex to classify"
A24: ! | B24: Delays providing contract data
A25: ! | B25: Procurement classifying everything as "strategic" to avoid scrutiny
A27: Service delivery framework elements — editable source (SOW Framework tab references here)
A28: Element | B28: What we do | C28: Admin tier | D28: Management tier | E28: Procurement tier
A29: Decision tree | B29: Integrate front-end decision technology | C29: — | D29: Support development of optimized decision tree, reporting on channel engagement | E29: Responsible for reviewing the 'work to be done' and advising on recommended channel, contracting/engagement and supplier options
A30: Contract/engagement structure verification | B30: Report on supplier performance, cost optimization and opportunities to develop the supply chain | C30: — | D30: Consult on contract/engagement structure best practices | E30: Responsible for validation of proposed contract/engagement structure to ensure compliance with policy and legislation
A32: KPIs for this phase — editable source (KPI Library tab references here)
A33: Metric | B33: Category | C33: Description | D33: Data source / responsibility | E33: Comment
A34: Worker classification distribution | B34: Program management | C34: Percentage of correctly classified resources (e.g., contractor vs. T&M vs. deliverable-based) | D34: VMS (MSP) / Workday (Client)
A35: Purchasing policy compliance rate | B35: Program management | C35: Percentage of SOWs processed outside of the program | D35: Offline | E35: Manual tracking
A36: Spend under management | B36: Program management | C36: Total SOW spend managed through the MSP program vs. unmanaged spend | D36: VMS (MSP) / FMS (Client) | E36: Requires access to client spend reporting
A37: Risk flag rate | B37: Compliance & governance | C37: Number of SOWs flagged for potential misclassification or non-compliance | D37: VMS (MSP) | E37: Tracking managed in CW module
A38: Audit findings | B38: Compliance & governance | C38: Number and severity of issues identified during internal or external audits | D38: Offline | E38: Audit report

Sheet Phase 2 — Admin Processing
A1: Phase 2 — Administrative processing
A2: Timeline: 4–8 months | Focus: Own execution, not sourcing
A3: Objective
B4: Take ownership of execution and record-keeping without touching sourcing decisions. Demonstrate operational reliability — the credibility that earns the right to Phase 3.
A5: Stakeholder dynamics
B6: Procurement still owns sourcing and supplier relationships — no threat yet. HR/IT benefit from automation and become allies. Hiring managers see faster onboarding as a win.
A7: Key activities
A8: 1. | B8: Ingest all executed agreements into the managed services platform (structured data, not just PDFs)
A9: 2. | B9: Worker identification: link individual contractors/consultants to their governing SOW
A10: 3. | B10: Automate worker onboarding triggered by SOW execution (system access, badge, orientation)
A11: 4. | B11: Automate offboarding triggered by SOW expiry or termination (access revocation, equipment return)
A12: 5. | B12: Build audit trail: who is working, under what agreement, at what rate, against what deliverable
A13: 6. | B13: Compliance monitoring: flag workers active without a current executed SOW
A14: Tooling
A15: 1. | B15: VMS or SOW management platform (worker-level tracking)
A16: 2. | B16: HRIS / identity management integration for onboarding/offboarding triggers
A17: 3. | B17: Compliance dashboard (workers without valid SOW, expired agreements)
A18: Success metrics
A19: ✓ | B19: % of workers tied to an active, executed SOW
A20: ✓ | B20: Onboarding cycle time reduction vs. baseline
A21: ✓ | B21: Offboarding compliance rate (access revocation within SLA)
A22: ✓ | B22: SOW coverage rate — workers with no governing agreement (target: zero)
A23: ✓ | B23: Data quality score in platform
A24: Resistance signals — watch for these
A25: ! | B25: "We don't want all workers in one system — our suppliers have their own processes"
A26: ! | B26: IT/security concerns used to stall integration work
A27: ! | B27: Manual workarounds maintained in parallel as a fallback
A29: Service delivery framework elements — editable source (SOW Framework tab references here)
A30: Element | B30: What we do | C30: Admin tier | D30: Management tier | E30: Procurement tier
A31: Requisition and authorization | B31: Integrate front-end decision technology | C31: Ad-hoc assistance to managers in requisition process and confirming compliance with approval process | D31: Providing support to assisting managers in requisition process and confirming compliance with approval process | E31: Responsible for assisting managers in requisition process and confirming compliance with approval process
A32: Vendor/supplier contracting — pay agent | B32: Report on supplier performance, cost optimization and opportunities to develop the supply chain | C32: Responsible for negotiation and execution of pay agent agreement and admin support to client execution of MSA/TPA | D32: Responsible for negotiation and execution of pay agent agreement and negotiation support to client in execution of MSA/TPA | E32: Responsible for negotiation and execution of pay agent agreement and admin support to client in negotiation and execution of MSA/TPA
A33: Statement of work | B33: Prepare statements of work & contracts for delivery of services, uploading into client VMS platform | C33: Responsible for capture and upload of statement of work | D33: Responsible for reporting volume, quality of SOWs, highlighting opportunities for optimization | E33: Responsible, with managers, for defining, drafting, negotiation of statement of work
A34: Compliance confirmation | B34: Extract the people-related data & highlight gaps and support the client to get them filled | C34: Responsible for confirming workers/contractors/vendor personnel have completed background screening in compliance with policy | D34: Responsible for confirming workers/contractors/vendor personnel have completed background screening in compliance with policy | E34: Responsible for confirming workers/contractors/vendor personnel have completed background screening in compliance with policy
A35: Onboard | B35: Extract the people-related data & highlight gaps and support the client to get them filled | C35: Capture of workers/contractors/vendor personnel onto client-side system to initiate onboarding processes | D35: Capture of workers/contractors/vendor personnel onto client-side system to initiate onboarding processes | E35: Responsible for capture of workers/contractors/vendor personnel details onto client-side system to initiate onboarding processes
A36: Start and induction | B36: Extract the people-related data & highlight gaps and support the client to get them filled | C36: Responsible for confirming start of workers/contractors/vendor personnel | D36: Responsible for confirming start of workers/contractors/vendor personnel | E36: Responsible for confirming start of workers/contractors/vendor personnel
A37: Query support | B37: Manage stakeholder, procurement and vendor enquiries | C37: Responsible for providing first-line query management support to workers/contractors/vendor personnel | D37: Responsible for providing first-line query management support to workers/contractors/vendor personnel | E37: Responsible for providing first-line query management support to workers/contractors/vendor personnel
A38: Amendments/extensions/changes | B38: Proactively manage the data in the VMS tech platform | C38: Responsible for capture of amendments/extensions/changes onto client-side system | D38: Responsible for reporting of SOWs that require changes/amendments | E38: Responsible for reporting and management of SOWs that require changes/amendments
A39: Time/materials/milestone/expense | B39: Proactively manage the data in the VMS tech platform | C39: Responsible for capturing and calculating time/materials/milestones/expenses | D39: Responsible for capturing and calculating time/materials/milestones/expenses | E39: Responsible for capturing and calculating time/materials/milestones/expenses
A40: Pay bill/payroll/benefits — principal | B40: Report on data consistency, quality & track client projects | C40: Responsible for distribution of payments to vendors/suppliers/workers/contractors | D40: Responsible for distribution of payments to vendors/suppliers/workers/contractors | E40: Responsible for distribution of payments to vendors/suppliers/workers/contractors
A41: Pay bill/payroll/benefits — pay agent | B41: Report on data consistency, quality & track client projects | C41: Accountable for distribution of payments to vendors/suppliers/workers/contractors | D41: Accountable for distribution of payments to vendors/suppliers/workers/contractors | E41: Accountable for distribution of payments to vendors/suppliers/workers/contractors
...

Sheet Phase 3 — Sourcing Assistance
A1: Phase 3 — Sourcing assistance (tail-end spend)
A2: Timeline: 6–12 months | Focus: Lead sub-threshold sourcing
A3: Objective
B4: Take the lead on sourcing activity below a defined spend threshold. Demonstrate that the managed services function can do sourcing well — not just process it. Build the PSL.
A5: Stakeholder dynamics
B6: Identity friction begins here. Frame as bandwidth relief, not displacement. Procurement oversight must be real (approval, not rubber stamp). Strong sponsor needed to hold the threshold line when exceptions are pushed.
A7: Key activities
A8: 1. | B8: Negotiate and document spend threshold with Procurement (e.g., SOWs under $X led by managed services with oversight)
A9: 2. | B9: Develop Preferred Supplier List (PSL): qualify suppliers by category, establish rate cards, SLAs, and performance criteria
A10: 3. | B10: Engage hiring managers directly on sub-threshold engagements — guide supplier selection, scope definition, commercial terms
A11: 4. | B11: Execute sub-threshold SOWs using pre-approved templates and pre-identified supplier panels
A12: 5. | B12: Track and report sourcing outcomes: savings vs. baseline, cycle time, supplier performance
A13: 6. | B13: Begin category-level spend analysis to inform PSL expansion
A14: Tooling
A15: 1. | B15: Supplier portal / PSL management
A16: 2. | B16: Rate card benchmarking data
A17: 3. | B17: Sourcing workflow tool (RFQ templates for sub-threshold use)
A18: 4. | B18: Savings tracking and reporting
A19: Success metrics
A20: ✓ | B20: Threshold defined and documented (with Procurement sign-off)
A21: ✓ | B21: PSL established — minimum 2–3 suppliers per major category
A22: ✓ | B22: % of sub-threshold spend routed through managed services
A23: ✓ | B23: Savings delivered vs. prior-year baseline
A24: ✓ | B24: Hiring manager satisfaction score
A25: ✓ | B25: Sourcing cycle time vs. benchmark
A26: Resistance signals — watch for these
A27: ! | B27: Procurement reclassifies spend upward to stay above the threshold
A28: ! | B28: "Our suppliers won't work with a third-party intermediary"
A29: ! | B29: Hiring managers bypass the process with direct supplier calls before engaging managed services
A30: ! | B30: Exception volume grows until the threshold is meaningless
A32: Service delivery framework elements — editable source (SOW Framework tab references here)
A33: Element | B33: What we do | C33: Admin tier | D33: Management tier | E33: Procurement tier
A34: Workforce and demand planning | B34: Provide insight and recommend projects to reduce costs | C34: — | D34: Support demand planning | E34: Responsible, with managers, for identifying projected workforce demand
A35: Market insights | B35: Provide insight and recommend projects to reduce costs | C35: — | D35: Provide annual/bi-annual market insights | E35: Responsible for periodic and ad hoc insights into skills availability/heat map and speed/cost to engage
A36: Salary/rate/cost benchmarking | B36: Integrate dynamic pricing & benchmarking technology | C36: — | D36: Provide annual/bi-annual benchmark for categories | E36: Responsible for providing periodic cost benchmark/analysis
A37: Vendor/supplier strategy | B37: Integrate dynamic pricing & benchmarking technology | C37: — | D37: Support refinement and establishment of category strategies via workshops and expertise | E37: Responsible for defining, developing and enacting a supplier engagement strategy including performance reviews and benchmarking to identify, onboard, measure and audit suppliers including diverse and minority-owned
A38: Vendor/supplier contracting — principal | B38: Report on supplier performance, cost optimization and opportunities to develop the supply chain | C38: Administration of execution of MSA/TPA | D38: Administration of execution of MSA/TPA, and input to negotiation approach as needed | E38: Responsible for negotiation and execution of MSA/TPA
A39: Sourcing toolkits | B39: Integrate front-end decision technology | C39: — | D39: Review and refine existing sourcing toolkits | E39: Responsible for designing, generating and distributing a sourcing toolkit for managers
A40: Consultation — role/project scoping | B40: Tender the requirements to the supply chain | C40: — | D40: Consult on project scoping best practices | E40: Responsible for consulting with manager to define scope of work including deliverables
A41: Vendor/supplier/bidder engagement | B41: Provide insight and recommend projects to reduce costs | C41: — | D41: Support the identification and vetting of vendors/suppliers/bidders | E41: Responsible, with managers, for identifying and engaging suitable vendors/suppliers/bidders
...

Sheet Phase 4 — RFx Support
A1: Phase 4 — RFx support and strategic sourcing partnership
A2: Timeline: 12+ months | Focus: Partner on strategic spend
A3: Objective
B4: Extend capabilities into competitive sourcing events and strategic spend. The patterning model: managed services runs the process, Procurement owns the decision.
A5: Stakeholder dynamics
B6: Procurement must see managed services as a capability multiplier, not a replacement. Sponsor role shifts from mandate-enforcer to relationship steward. Procurement leaders who resisted Phase 3 often become advocates here.
A7: Key activities
A8: 1. | B8: Lead or co-lead RFx processes (RFI, RFP, RFQ) for above-threshold spend in partnership with Procurement
A9: 2. | B9: Conduct bid management: supplier outreach, response evaluation, negotiation support
A10: 3. | B10: Develop category strategies for high-spend areas with Procurement category managers
A11: 4. | B11: Pattern with Procurement: managed services runs the process, Procurement owns the decision
A12: 5. | B12: Feed market intelligence and supplier performance data back into PSL and rate benchmarks
A13: 6. | B13: Establish governance cadence: regular review of sourcing outcomes, threshold adjustments, PSL changes
A14: Tooling
A15: 1. | B15: RFx platform (e-sourcing)
A16: 2. | B16: Contract lifecycle management (CLM) integration
A17: 3. | B17: Supplier performance management / scorecard
A18: 4. | B18: Category spend analytics
A19: Success metrics
A20: ✓ | B20: Number and value of RFx events supported
A21: ✓ | B21: Savings delivered on above-threshold competitive events
A22: ✓ | B22: Time-to-award vs. benchmark
A23: ✓ | B23: Procurement satisfaction with partnership model (quarterly)
A24: ✓ | B24: Category coverage: % of spend with documented category strategy
A25: ✓ | B25: PSL utilization rate
A26: Resistance signals — watch for these
A27: ! | B27: Procurement wants managed services in support role only — reverting to Phase 2 dynamic
A28: ! | B28: Threshold creep upward as managed services takes on more without formal recognition
A29: ! | B29: Managed services seen as competing for Procurement headcount rather than augmenting it
A31: Service delivery framework elements — editable source (SOW Framework tab references here)
A32: Element | B32: What we do | C32: Admin tier | D32: Management tier | E32: Procurement tier
A33: RFx launch | B33: Implement client projects delivering agreed benefits | C33: — | D33: Responsible for the facilitation of the RFx | E33: Responsible, with managers, for defining, drafting and launching RFx process and documents to selected vendors/suppliers/bidders
A34: RFx review/assessment | B34: Implement client projects delivering agreed benefits | C34: — | D34: Responsible for facilitation of RFx assessment | E34: Responsible, with managers, for reviewing and assessing RFx responses from vendors/suppliers/bidders to identify shortlisted bidders
A35: RFx negotiation | B35: Negotiate options for supply | C35: — | D35: Support negotiations | E35: Responsible, with managers, for negotiation with vendors/suppliers/bidders to identify preferred bidders
A37: KPIs for this phase — editable source (KPI Library tab references here)
A38: Metric | B38: Category | C38: Description | D38: Data source / responsibility | E38: Comment
A39: Bid activity ratio | B39: Operational efficiency | C39: Ratio of SOWs that are sourced through VMS | D39: VMS (MSP)
A40: Bid (RFP) pipeline efficiency | B40: Operational efficiency | C40: Ratio of acceptable bids received per opportunity | D40: VMS (MSP)
A41: Invoice accuracy rate | B41: Financial & cost | C41: Percentage of invoices aligned with agreed milestones, rates, and deliverables processed without errors | D41: FMS (Client) / Supplier | E41: Invoice error rate reporting from client AP
A42: Milestone achievement rate | B42: Supplier & vendor performance | C42: Percentage of deliverables or milestones completed on time | D42: VMS (MSP)
...

Sheet SOW Framework
A1: SOW framework — service tier responsibilities (compiled from phase tabs)
A2: Formulas reference phase tabs. Edit data on the relevant phase tab — this view updates automatically.
A3: Phase | B3: Element | C3: What we do | D3: Admin tier | E3: Management tier | F3: Procurement tier
A4: Phase 1 elements
A5: 1 | B5: ='Phase 1 — Classification'!A29 | C5: ='Phase 1 — Classification'!B29 | D5: ='Phase 1 — Classification'!C29 | E5: ='Phase 1 — Classification'!D29 | F5: ='Phase 1 — Classification'!E29
A6: 1 | B6: ='Phase 1 — Classification'!A30 | C6: ='Phase 1 — Classification'!B30 | D6: ='Phase 1 — Classification'!C30 | E6: ='Phase 1 — Classification'!D30 | F6: ='Phase 1 — Classification'!E30
A7: Phase 2 elements
A8: 2 | B8: ='Phase 2 — Admin Processing'!A31 | C8: ='Phase 2 — Admin Processing'!B31 | D8: ='Phase 2 — Admin Processing'!C31 | E8: ='Phase 2 — Admin Processing'!D31 | F8: ='Phase 2 — Admin Processing'!E31
A9: 2 | B9: ='Phase 2 — Admin Processing'!A32 | C9: ='Phase 2 — Admin Processing'!B32 | D9: ='Phase 2 — Admin Processing'!C32 | E9: ='Phase 2 — Admin Processing'!D32 | F9: ='Phase 2 — Admin Processing'!E32
A10: 2 | B10: ='Phase 2 — Admin Processing'!A33 | C10: ='Phase 2 — Admin Processing'!B33 | D10: ='Phase 2 — Admin Processing'!C33 | E10: ='Phase 2 — Admin Processing'!D33 | F10: ='Phase 2 — Admin Processing'!E33
A11: 2 | B11: ='Phase 2 — Admin Processing'!A34 | C11: ='Phase 2 — Admin Processing'!B34 | D11: ='Phase 2 — Admin Processing'!C34 | E11: ='Phase 2 — Admin Processing'!D34 | F11: ='Phase 2 — Admin Processing'!E34
A12: 2 | B12: ='Phase 2 — Admin Processing'!A35 | C12: ='Phase 2 — Admin Processing'!B35 | D12: ='Phase 2 — Admin Processing'!C35 | E12: ='Phase 2 — Admin Processing'!D35 | F12: ='Phase 2 — Admin Processing'!E35
A13: 2 | B13: ='Phase 2 — Admin Processing'!A36 | C13: ='Phase 2 — Admin Processing'!B36 | D13: ='Phase 2 — Admin Processing'!C36 | E13: ='Phase 2 — Admin Processing'!D36 | F13: ='Phase 2 — Admin Processing'!E36
A14: 2 | B14: ='Phase 2 — Admin Processing'!A37 | C14: ='Phase 2 — Admin Processing'!B37 | D14: ='Phase 2 — Admin Processing'!C37 | E14: ='Phase 2 — Admin Processing'!D37 | F14: ='Phase 2 — Admin Processing'!E37
A15: 2 | B15: ='Phase 2 — Admin Processing'!A38 | C15: ='Phase 2 — Admin Processing'!B38 | D15: ='Phase 2 — Admin Processing'!C38 | E15: ='Phase 2 — Admin Processing'!D38 | F15: ='Phase 2 — Admin Processing'!E38
A16: 2 | B16: ='Phase 2 — Admin Processing'!A39 | C16: ='Phase 2 — Admin Processing'!B39 | D16: ='Phase 2 — Admin Processing'!C39 | E16: ='Phase 2 — Admin Processing'!D39 | F16: ='Phase 2 — Admin Processing'!E39
A17: 2 | B17: ='Phase 2 — Admin Processing'!A40 | C17: ='Phase 2 — Admin Processing'!B40 | D17: ='Phase 2 — Admin Processing'!C40 | E17: ='Phase 2 — Admin Processing'!D40 | F17: ='Phase 2 — Admin Processing'!E40
A18: 2 | B18: ='Phase 2 — Admin Processing'!A41 | C18: ='Phase 2 — Admin Processing'!B41 | D18: ='Phase 2 — Admin Processing'!C41 | E18: ='Phase 2 — Admin Processing'!D41 | F18: ='Phase 2 — Admin Processing'!E41
A19: 2 | B19: ='Phase 2 — Admin Processing'!A42 | C19: ='Phase 2 — Admin Processing'!B42 | D19: ='Phase 2 — Admin Processing'!C42 | E19: ='Phase 2 — Admin Processing'!D42 | F19: ='Phase 2 — Admin Processing'!E42
... A21: 2 | B21: ='Phase 2 — Admin Processing'!A44 | C21: ='Phase 2 — Admin Processing'!B44 | D21: ='Phase 2 — Admin Processing'!C44 | E21: ='Phase 2 — Admin Processing'!D44 | F21: ='Phase 2 — Admin Processing'!E44
A22: Phase 3 elements
A23: 3 | B23: ='Phase 3 — Sourcing Assistance'!A34 | C23: ='Phase 3 — Sourcing Assistance'!B34 | D23: ='Phase 3 — Sourcing Assistance'!C34 | E23: ='Phase 3 — Sourcing Assistance'!D34 | F23: ='Phase 3 — Sourcing Assistance'!E34
A24: 3 | B24: ='Phase 3 — Sourcing Assistance'!A35 | C24: ='Phase 3 — Sourcing Assistance'!B35 | D24: ='Phase 3 — Sourcing Assistance'!C35 | E24: ='Phase 3 — Sourcing Assistance'!D35 | F24: ='Phase 3 — Sourcing Assistance'!E35
A25: 3 | B25: ='Phase 3 — Sourcing Assistance'!A36 | C25: ='Phase 3 — Sourcing Assistance'!B36 | D25: ='Phase 3 — Sourcing Assistance'!C36 | E25: ='Phase 3 — Sourcing Assistance'!D36 | F25: ='Phase 3 — Sourcing Assistance'!E36
A26: 3 | B26: ='Phase 3 — Sourcing Assistance'!A37 | C26: ='Phase 3 — Sourcing Assistance'!B37 | D26: ='Phase 3 — Sourcing Assistance'!C37 | E26: ='Phase 3 — Sourcing Assistance'!D37 | F26: ='Phase 3 — Sourcing Assistance'!E37
A27: 3 | B27: ='Phase 3 — Sourcing Assistance'!A38 | C27: ='Phase 3 — Sourcing Assistance'!B38 | D27: ='Phase 3 — Sourcing Assistance'!C38 | E27: ='Phase 3 — Sourcing Assistance'!D38 | F27: ='Phase 3 — Sourcing Assistance'!E38
A28: 3 | B28: ='Phase 3 — Sourcing Assistance'!A39 | C28: ='Phase 3 — Sourcing Assistance'!B39 | D28: ='Phase 3 — Sourcing Assistance'!C39 | E28: ='Phase 3 — Sourcing Assistance'!D39 | F28: ='Phase 3 — Sourcing Assistance'!E39
A29: 3 | B29: ='Phase 3 — Sourcing Assistance'!A40 | C29: ='Phase 3 — Sourcing Assistance'!B40 | D29: ='Phase 3 — Sourcing Assistance'!C40 | E29: ='Phase 3 — Sourcing Assistance'!D40 | F29: ='Phase 3 — Sourcing Assistance'!E40
A30: 3 | B30: ='Phase 3 — Sourcing Assistance'!A41 | C30: ='Phase 3 — Sourcing Assistance'!B41 | D30: ='Phase 3 — Sourcing Assistance'!C41 | E30: ='Phase 3 — Sourcing Assistance'!D41 | F30: ='Phase 3 — Sourcing Assistance'!E41
A31: Phase 4 elements
A32: 4 | B32: ='Phase 4 — RFx Support'!A33 | C32: ='Phase 4 — RFx Support'!B33 | D32: ='Phase 4 — RFx Support'!C33 | E32: ='Phase 4 — RFx Support'!D33 | F32: ='Phase 4 — RFx Support'!E33
A33: 4 | B33: ='Phase 4 — RFx Support'!A34 | C33: ='Phase 4 — RFx Support'!B34 | D33: ='Phase 4 — RFx Support'!C34 | E33: ='Phase 4 — RFx Support'!D34 | F33: ='Phase 4 — RFx Support'!E34
A34: 4 | B34: ='Phase 4 — RFx Support'!A35 | C34: ='Phase 4 — RFx Support'!B35 | D34: ='Phase 4 — RFx Support'!C35 | E34: ='Phase 4 — RFx Support'!D35 | F34: ='Phase 4 — RFx Support'!E35

Sheet KPI Library
A1: KPI library — compiled from phase tabs
A2: Formulas reference phase tabs. Edit data on the relevant phase tab — this view updates automatically.
A3: Phase | B3: Metric | C3: Category | D3: Description | E3: Data source / responsibility | F3: Comment
A4: Phase 1 KPIs
A5: 1 | B5: ='Phase 1 — Classification'!A34 | C5: ='Phase 1 — Classification'!B34 | D5: ='Phase 1 — Classification'!C34 | E5: ='Phase 1 — Classification'!D34 | F5: ='Phase 1 — Classification'!E34
A6: 1 | B6: ='Phase 1 — Classification'!A35 | C6: ='Phase 1 — Classification'!B35 | D6: ='Phase 1 — Classification'!C35 | E6: ='Phase 1 — Classification'!D35 | F6: ='Phase 1 — Classification'!E35
A7: 1 | B7: ='Phase 1 — Classification'!A36 | C7: ='Phase 1 — Classification'!B36 | D7: ='Phase 1 — Classification'!C36 | E7: ='Phase 1 — Classification'!D36 | F7: ='Phase 1 — Classification'!E36
A8: 1 | B8: ='Phase 1 — Classification'!A37 | C8: ='Phase 1 — Classification'!B37 | D8: ='Phase 1 — Classification'!C37 | E8: ='Phase 1 — Classification'!D37 | F8: ='Phase 1 — Classification'!E37
A9: 1 | B9: ='Phase 1 — Classification'!A38 | C9: ='Phase 1 — Classification'!B38 | D9: ='Phase 1 — Classification'!C38 | E9: ='Phase 1 — Classification'!D38 | F9: ='Phase 1 — Classification'!E38
A10: Phase 2 KPIs
A11: 2 | B11: ='Phase 2 — Admin Processing'!A48 | C11: ='Phase 2 — Admin Processing'!B48 | D11: ='Phase 2 — Admin Processing'!C48 | E11: ='Phase 2 — Admin Processing'!D48 | F11: ='Phase 2 — Admin Processing'!E48
A12: 2 | B12: ='Phase 2 — Admin Processing'!A49 | C12: ='Phase 2 — Admin Processing'!B49 | D12: ='Phase 2 — Admin Processing'!C49 | E12: ='Phase 2 — Admin Processing'!D49 | F12: ='Phase 2 — Admin Processing'!E49
A13: 2 | B13: ='Phase 2 — Admin Processing'!A50 | C13: ='Phase 2 — Admin Processing'!B50 | D13: ='Phase 2 — Admin Processing'!C50 | E13: ='Phase 2 — Admin Processing'!D50 | F13: ='Phase 2 — Admin Processing'!E50
A14: 2 | B14: ='Phase 2 — Admin Processing'!A51 | C14: ='Phase 2 — Admin Processing'!B51 | D14: ='Phase 2 — Admin Processing'!C51 | E14: ='Phase 2 — Admin Processing'!D51 | F14: ='Phase 2 — Admin Processing'!E51
A15: 2 | B15: ='Phase 2 — Admin Processing'!A52 | C15: ='Phase 2 — Admin Processing'!B52 | D15: ='Phase 2 — Admin Processing'!C52 | E15: ='Phase 2 — Admin Processing'!D52 | F15: ='Phase 2 — Admin Processing'!E52
A16: 2 | B16: ='Phase 2 — Admin Processing'!A53 | C16: ='Phase 2 — Admin Processing'!B53 | D16: ='Phase 2 — Admin Processing'!C53 | E16: ='Phase 2 — Admin Processing'!D53 | F16: ='Phase 2 — Admin Processing'!E53
A17: 2 | B17: ='Phase 2 — Admin Processing'!A54 | C17: ='Phase 2 — Admin Processing'!B54 | D17: ='Phase 2 — Admin Processing'!C54 | E17: ='Phase 2 — Admin Processing'!D54 | F17: ='Phase 2 — Admin Processing'!E54
A18: 2 | B18: ='Phase 2 — Admin Processing'!A55 | C18: ='Phase 2 — Admin Processing'!B55 | D18: ='Phase 2 — Admin Processing'!C55 | E18: ='Phase 2 — Admin Processing'!D55 | F18: ='Phase 2 — Admin Processing'!E55
A19: 2 | B19: ='Phase 2 — Admin Processing'!A56 | C19: ='Phase 2 — Admin Processing'!B56 | D19: ='Phase 2 — Admin Processing'!C56 | E19: ='Phase 2 — Admin Processing'!D56 | F19: ='Phase 2 — Admin Processing'!E56
A20: 2 | B20: ='Phase 2 — Admin Processing'!A57 | C20: ='Phase 2 — Admin Processing'!B57 | D20: ='Phase 2 — Admin Processing'!C57 | E20: ='Phase 2 — Admin Processing'!D57 | F20: ='Phase 2 — Admin Processing'!E57
A21: 2 | B21: ='Phase 2 — Admin Processing'!A58 | C21: ='Phase 2 — Admin Processing'!B58 | D21: ='Phase 2 — Admin Processing'!C58 | E21: ='Phase 2 — Admin Processing'!D58 | F21: ='Phase 2 — Admin Processing'!E58
A22: 2 | B22: ='Phase 2 — Admin Processing'!A59 | C22: ='Phase 2 — Admin Processing'!B59 | D22: ='Phase 2 — Admin Processing'!C59 | E22: ='Phase 2 — Admin Processing'!D59 | F22: ='Phase 2 — Admin Processing'!E59
A23: Phase 3 KPIs
A24: 3 | B24: ='Phase 3 — Sourcing Assistance'!A45 | C24: ='Phase 3 — Sourcing Assistance'!B45 | D24: ='Phase 3 — Sourcing Assistance'!C45 | E24: ='Phase 3 — Sourcing Assistance'!D45 | F24: ='Phase 3 — Sourcing Assistance'!E45
A25: 3 | B25: ='Phase 3 — Sourcing Assistance'!A46 | C25: ='Phase 3 — Sourcing Assistance'!B46 | D25: ='Phase 3 — Sourcing Assistance'!C46 | E25: ='Phase 3 — Sourcing Assistance'!D46 | F25: ='Phase 3 — Sourcing Assistance'!E46
A26: 3 | B26: ='Phase 3 — Sourcing Assistance'!A47 | C26: ='Phase 3 — Sourcing Assistance'!B47 | D26: ='Phase 3 — Sourcing Assistance'!C47 | E26: ='Phase 3 — Sourcing Assistance'!D47 | F26: ='Phase 3 — Sourcing Assistance'!E47
A27: 3 | B27: ='Phase 3 — Sourcing Assistance'!A48 | C27: ='Phase 3 — Sourcing Assistance'!B48 | D27: ='Phase 3 — Sourcing Assistance'!C48 | E27: ='Phase 3 — Sourcing Assistance'!D48 | F27: ='Phase 3 — Sourcing Assistance'!E48
A28: 3 | B28: ='Phase 3 — Sourcing Assistance'!A49 | C28: ='Phase 3 — Sourcing Assistance'!B49 | D28: ='Phase 3 — Sourcing Assistance'!C49 | E28: ='Phase 3 — Sourcing Assistance'!D49 | F28: ='Phase 3 — Sourcing Assistance'!E49
A29: 3 | B29: ='Phase 3 — Sourcing Assistance'!A50 | C29: ='Phase 3 — Sourcing Assistance'!B50 | D29: ='Phase 3 — Sourcing Assistance'!C50 | E29: ='Phase 3 — Sourcing Assistance'!D50 | F29: ='Phase 3 — Sourcing Assistance'!E50
A30: 3 | B30: ='Phase 3 — Sourcing Assistance'!A51 | C30: ='Phase 3 — Sourcing Assistance'!B51 | D30: ='Phase 3 — Sourcing Assistance'!C51 | E30: ='Phase 3 — Sourcing Assistance'!D51 | F30: ='Phase 3 — Sourcing Assistance'!E51
A31: 3 | B31: ='Phase 3 — Sourcing Assistance'!A52 | C31: ='Phase 3 — Sourcing Assistance'!B52 | D31: ='Phase 3 — Sourcing Assistance'!C52 | E31: ='Phase 3 — Sourcing Assistance'!D52 | F31: ='Phase 3 — Sourcing Assistance'!E52
A32: 3 | B32: ='Phase 3 — Sourcing Assistance'!A53 | C32: ='Phase 3 — Sourcing Assistance'!B53 | D32: ='Phase 3 — Sourcing Assistance'!C53 | E32: ='Phase 3 — Sourcing Assistance'!D53 | F32: ='Phase 3 — Sourcing Assistance'!E53
A33: 3 | B33: ='Phase 3 — Sourcing Assistance'!A54 | C33: ='Phase 3 — Sourcing Assistance'!B54 | D33: ='Phase 3 — Sourcing Assistance'!C54 | E33: ='Phase 3 — Sourcing Assistance'!D54 | F33: ='Phase 3 — Sourcing Assistance'!E54
A34: 3 | B34: ='Phase 3 — Sourcing Assistance'!A55 | C34: ='Phase 3 — Sourcing Assistance'!B55 | D34: ='Phase 3 — Sourcing Assistance'!C55 | E34: ='Phase 3 — Sourcing Assistance'!D55 | F34: ='Phase 3 — Sourcing Assistance'!E55
A35: Phase 4 KPIs
A36: 4 | B36: ='Phase 4 — RFx Support'!A39 | C36: ='Phase 4 — RFx Support'!B39 | D36: ='Phase 4 — RFx Support'!C39 | E36: ='Phase 4 — RFx Support'!D39 | F36: ='Phase 4 — RFx Support'!E39
A37: 4 | B37: ='Phase 4 — RFx Support'!A40 | C37: ='Phase 4 — RFx Support'!B40 | D37: ='Phase 4 — RFx Support'!C40 | E37: ='Phase 4 — RFx Support'!D40 | F37: ='Phase 4 — RFx Support'!E40
A38: 4 | B38: ='Phase 4 — RFx Support'!A41 | C38: ='Phase 4 — RFx Support'!B41 | D38: ='Phase 4 — RFx Support'!C41 | E38: ='Phase 4 — RFx Support'!D41 | F38: ='Phase 4 — RFx Support'!E41
A39: 4 | B39: ='Phase 4 — RFx Support'!A42 | C39: ='Phase 4 — RFx Support'!B42 | D39: ='Phase 4 — RFx Support'!C42 | E39: ='Phase 4 — RFx Support'!D42 | F39: ='Phase 4 — RFx Support'!E42
A40: 4 | B40: ='Phase 4 — RFx Support'!A43 | C40: ='Phase 4 — RFx Support'!B43 | D40: ='Phase 4 — RFx Support'!C43 | E40: ='Phase 4 — RFx Support'!D43 | F40: ='Phase 4 — RFx Support'!E43
...

Sheet For Review
A1: For review — items pending phase assignment
A2: These items have no clear phase assignment. Assign each to a phase tab, then move them there and delete from this sheet. The master tabs (SOW Framework, KPI Library) will update via formula.
A3: Metric / element | B3: Category | C3: Description | D3: Data source | E3: Comment
A4: MSP internal — financial
A5: Gross margin per SOW | B5: MSP internal — financial | C5: Profitability of each SOW after direct costs | D5: VMS (MSP) / Offline | E5: For internal use only
A6: Revenue per client | B6: MSP internal — financial | C6: Total revenue generated per client account | D6: VMS (MSP) / Offline | E6: For internal use only
A7: Cost of service delivery per client | B7: MSP internal — financial | C7: Total operational cost to deliver services to client | D7: Offline | E7: For internal use only
A8: Client profitability index | B8: MSP internal — financial | C8: Ratio of revenue to cost per client | D8: VMS (MSP) / Offline | E8: For internal use only
A9: Revenue per portfolio | B9: MSP internal — financial | C9: Total revenue generated across portfolio | D9: VMS (MSP) / Offline | E9: For internal use only
A10: Cost of service delivery | B10: MSP internal — financial | C10: Total operational cost to deliver services across accounts | D10: VMS (MSP) / Offline | E10: For internal use only
A11: MSP internal — workforce
A12: SOW resource utilization rate | B12: MSP internal — workforce | C12: Percentage of MSP staff time transacting SOW activities | D12: Offline
A13: Annual SOW limit | B13: MSP internal — workforce | C13: Annual number of SOWs that a resource can process | D13: Offline
A14: Employee retention rate | B14: MSP internal — workforce | C14: Percentage of MSP employees retained year-over-year | D14: Offline
A15: Training completion rate | B15: MSP internal — workforce | C15: Percentage of internal staff completing required certifications or client-specific training | D15: Offline
A16: Employee engagement score | B16: MSP internal — workforce | C16: Internal survey score reflecting team morale and engagement | D16: Offline
